<?xml version="1.0"?>
<robot name="six_dof_robotic_arm">

  <!-- Define joints -->
  <joint name="joint1" type="revolute">
    <parent link="base_link"/>
    <child link="link1"/>
    <origin xyz="0 0 0" rpy="0 0 0"/>
    <axis xyz="0 0 1"/>
    <limit lower="-1.57079" upper="1.57079" effort="100" velocity="3.14"/>
  </joint>

  <joint name="joint2" type="revolute">
    <parent link="link1"/>
    <child link="link2"/>
    <origin xyz="0 0 14" rpy="0 0 0"/>
    <axis xyz="1 0 0"/>
    <limit lower="0" upper="3.66519" effort="100" velocity="3.14"/>
  </joint>

  <joint name="joint3" type="revolute">
    <parent link="link2"/>
    <child link="link3"/>
    <origin xyz="0 13 0" rpy="0.785398 0 0"/>
    <axis xyz="-1 0 0"/>
    <limit lower="0" upper="3.14159" effort="100" velocity="3.14"/>
  </joint>

  <!-- <joint name="wrist_1_joint" type="revolute">
    <parent link="link3"/>
    <child link="link4"/>
    <origin xyz="0.3 0 0" rpy="0 0 0"/>
    <axis xyz="0 1 0"/>
    <limit lower="-3.14159" upper="3.14159" effort="100" velocity="3.14"/>
  </joint>

  <joint name="wrist_2_joint" type="revolute">
    <parent link="link4"/>
    <child link="link5"/>
    <origin xyz="0.2 0 0" rpy="0 0 0"/>
    <axis xyz="0 0 1"/>
    <limit lower="-3.14159" upper="3.14159" effort="100" velocity="3.14"/>
  </joint>

  <joint name="wrist_3_joint" type="revolute">
    <parent link="link5"/>
    <child link="gripper_link"/>
    <origin xyz="0.1 0 0" rpy="0 0 0"/>
    <axis xyz="0 1 0"/>
    <limit lower="-3.14159" upper="3.14159" effort="100" velocity="3.14"/>
  </joint> -->

  <!-- Define materials -->
  <material name="black">
    <color rgba="0.0 0.0 0.0 1.0"/>
  </material>

  <!-- Define links -->
  <link name="base_link">
    <visual>
      <geometry>
        <box size="9.0 9.0 2.9"/>
      </geometry>
      <origin xyz="0 0 1.45" rpy="0 0 0"/>
      <material name="black"/>
    </visual>
  </link>

  <link name="link1">
    <visual>
      <geometry>
        <box size="2.5 6.5 12.2"/>
      </geometry>
      <origin xyz="0 1.5 9.0" rpy="0 0 0"/> <!-- Origin height (z) is 6.1 (half of object height) + 2.9 (base height) = 9.0 -->
      <material name="black"/>
    </visual>
  </link>

  <link name="link2">
    <visual>
      <geometry>
        <box size="6 13 2.5"/>
      </geometry>
      <origin xyz="0 6.5 0" rpy="0 0 0"/>
      <material name="black"/>
    </visual>
  </link>

  <link name="link3">
    <visual>
      <geometry>
        <box size="6 13 2.5"/>
      </geometry>
      <origin xyz="0 6.5 0" rpy="0 0 0"/>
      <material name="black"/>
    </visual>
  </link>

  <!-- <link name="link4">
    <visual>
      <geometry>
        <box size="0.3 0.1 0.1"/>
      </geometry>
    </visual>
  </link>

  <link name="link5">
    <visual>
      <geometry>
        <box size="0.2 0.1 0.1"/>
      </geometry>
    </visual>
  </link>

  <link name="gripper_link">
    <visual>
      <geometry>
        <box size="0.1 0.05 0.05"/>
      </geometry>
    </visual>
  </link> -->

  <!-- Define robot links and joints -->
  <!-- <link name="robot_link">
    <visual>
      <origin xyz="0 0 0" rpy="0 0 0"/>
      <geometry>
        <box size="0.05 0.05 0.05"/>
      </geometry>
    </visual>
  </link>

  <joint name="robot_base_joint" type="fixed">
    <parent link="base_link"/>
    <child link="robot_link"/>
    <origin xyz="0 0 0" rpy="0 0 0"/>
  </joint> -->

</robot>
